Traceback (most recent call last):
  File "/opt/hostedtoolcache/Python/3.9.7/x64/lib/python3.9/site-packages/jupyter_cache/executors/utils.py", line 51, in single_nb_execution
    executenb(
  File "/opt/hostedtoolcache/Python/3.9.7/x64/lib/python3.9/site-packages/nbclient/client.py", line 1117, in execute
    return NotebookClient(nb=nb, resources=resources, km=km, **kwargs).execute()
  File "/opt/hostedtoolcache/Python/3.9.7/x64/lib/python3.9/site-packages/nbclient/util.py", line 78, in wrapped
    return just_run(coro(*args, **kwargs))
  File "/opt/hostedtoolcache/Python/3.9.7/x64/lib/python3.9/site-packages/nbclient/util.py", line 57, in just_run
    return loop.run_until_complete(coro)
  File "/opt/hostedtoolcache/Python/3.9.7/x64/lib/python3.9/asyncio/base_events.py", line 642, in run_until_complete
    return future.result()
  File "/opt/hostedtoolcache/Python/3.9.7/x64/lib/python3.9/site-packages/nbclient/client.py", line 558, in async_execute
    await self.async_execute_cell(
  File "/opt/hostedtoolcache/Python/3.9.7/x64/lib/python3.9/site-packages/nbclient/client.py", line 862, in async_execute_cell
    self._check_raise_for_error(cell, exec_reply)
  File "/opt/hostedtoolcache/Python/3.9.7/x64/lib/python3.9/site-packages/nbclient/client.py", line 765, in _check_raise_for_error
    raise CellExecutionError.from_cell_and_msg(cell, exec_reply_content)
nbclient.exceptions.CellExecutionError: An error occurred while executing the following cell:
------------------
# Imports
from IPython.display import display, Markdown
from matplotlib_venn import venn3

import numpy as np
import scipy.integrate as integrate
import scipy.optimize as optimize
import scipy.stats as scipy_stats
import statsmodels.api as sm
import pandas as pd
import matplotlib.pyplot as plt

import statistics
import math
import utils
------------------

[0;31m---------------------------------------------------------------------------[0m
[0;31mModuleNotFoundError[0m                       Traceback (most recent call last)
[0;32m/tmp/ipykernel_1748/137612747.py[0m in [0;36m<module>[0;34m[0m
[1;32m      1[0m [0;31m# Imports[0m[0;34m[0m[0;34m[0m[0m
[1;32m      2[0m [0;32mfrom[0m [0mIPython[0m[0;34m.[0m[0mdisplay[0m [0;32mimport[0m [0mdisplay[0m[0;34m,[0m [0mMarkdown[0m[0;34m[0m[0;34m[0m[0m
[0;32m----> 3[0;31m [0;32mfrom[0m [0mmatplotlib_venn[0m [0;32mimport[0m [0mvenn3[0m[0;34m[0m[0;34m[0m[0m
[0m[1;32m      4[0m [0;34m[0m[0m
[1;32m      5[0m [0;32mimport[0m [0mnumpy[0m [0;32mas[0m [0mnp[0m[0;34m[0m[0;34m[0m[0m

[0;31mModuleNotFoundError[0m: No module named 'matplotlib_venn'
ModuleNotFoundError: No module named 'matplotlib_venn'

