Traceback (most recent call last):
  File "/opt/hostedtoolcache/Python/3.10.9/x64/lib/python3.10/site-packages/jupyter_cache/executors/utils.py", line 51, in single_nb_execution
    executenb(
  File "/opt/hostedtoolcache/Python/3.10.9/x64/lib/python3.10/site-packages/nbclient/client.py", line 1204, in execute
    return NotebookClient(nb=nb, resources=resources, km=km, **kwargs).execute()
  File "/opt/hostedtoolcache/Python/3.10.9/x64/lib/python3.10/site-packages/nbclient/util.py", line 84, in wrapped
    return just_run(coro(*args, **kwargs))
  File "/opt/hostedtoolcache/Python/3.10.9/x64/lib/python3.10/site-packages/nbclient/util.py", line 62, in just_run
    return loop.run_until_complete(coro)
  File "/opt/hostedtoolcache/Python/3.10.9/x64/lib/python3.10/asyncio/base_events.py", line 649, in run_until_complete
    return future.result()
  File "/opt/hostedtoolcache/Python/3.10.9/x64/lib/python3.10/site-packages/nbclient/client.py", line 663, in async_execute
    await self.async_execute_cell(
  File "/opt/hostedtoolcache/Python/3.10.9/x64/lib/python3.10/site-packages/nbclient/client.py", line 965, in async_execute_cell
    await self._check_raise_for_error(cell, cell_index, exec_reply)
  File "/opt/hostedtoolcache/Python/3.10.9/x64/lib/python3.10/site-packages/nbclient/client.py", line 862, in _check_raise_for_error
    raise CellExecutionError.from_cell_and_msg(cell, exec_reply_content)
nbclient.exceptions.CellExecutionError: An error occurred while executing the following cell:
------------------
import plotly.express as px

dados_carros = pd.read_table("./dados/CarData.txt", sep="\s+")

colunas_linhas_paralelas = [
    coluna for coluna in dados_carros.columns if coluna not in ["C", "Model"]
]

fig = px.parallel_coordinates(
    dados_carros,
    color="C",
    dimensions=colunas_linhas_paralelas,
    #color_continuous_scale=px.colors.diverging.RdYlBu,
)

fig.write_image("./imagens/trabalho1_q9.png")
------------------

[0;31m---------------------------------------------------------------------------[0m
[0;31mValueError[0m                                Traceback (most recent call last)
Input [0;32mIn [4][0m, in [0;36m<cell line: 16>[0;34m()[0m
[1;32m      5[0m colunas_linhas_paralelas [38;5;241m=[39m [
[1;32m      6[0m     coluna [38;5;28;01mfor[39;00m coluna [38;5;129;01min[39;00m dados_carros[38;5;241m.[39mcolumns [38;5;28;01mif[39;00m coluna [38;5;129;01mnot[39;00m [38;5;129;01min[39;00m [[38;5;124m"[39m[38;5;124mC[39m[38;5;124m"[39m, [38;5;124m"[39m[38;5;124mModel[39m[38;5;124m"[39m]
[1;32m      7[0m ]
[1;32m      9[0m fig [38;5;241m=[39m px[38;5;241m.[39mparallel_coordinates(
[1;32m     10[0m     dados_carros,
[1;32m     11[0m     color[38;5;241m=[39m[38;5;124m"[39m[38;5;124mC[39m[38;5;124m"[39m,
[1;32m     12[0m     dimensions[38;5;241m=[39mcolunas_linhas_paralelas,
[1;32m     13[0m     [38;5;66;03m#color_continuous_scale=px.colors.diverging.RdYlBu,[39;00m
[1;32m     14[0m )
[0;32m---> 16[0m [43mfig[49m[38;5;241;43m.[39;49m[43mwrite_image[49m[43m([49m[38;5;124;43m"[39;49m[38;5;124;43m./imagens/trabalho1_q9.png[39;49m[38;5;124;43m"[39;49m[43m)[49m

File [0;32m/opt/hostedtoolcache/Python/3.10.9/x64/lib/python3.10/site-packages/plotly/basedatatypes.py:3829[0m, in [0;36mBaseFigure.write_image[0;34m(self, *args, **kwargs)[0m
[1;32m   3769[0m [38;5;124;03m"""[39;00m
[1;32m   3770[0m [38;5;124;03mConvert a figure to a static image and write it to a file or writeable[39;00m
[1;32m   3771[0m [38;5;124;03mobject[39;00m
[0;32m   (...)[0m
[1;32m   3825[0m [38;5;124;03mNone[39;00m
[1;32m   3826[0m [38;5;124;03m"""[39;00m
[1;32m   3827[0m [38;5;28;01mimport[39;00m [38;5;21;01mplotly[39;00m[38;5;21;01m.[39;00m[38;5;21;01mio[39;00m [38;5;28;01mas[39;00m [38;5;21;01mpio[39;00m
[0;32m-> 3829[0m [38;5;28;01mreturn[39;00m [43mpio[49m[38;5;241;43m.[39;49m[43mwrite_image[49m[43m([49m[38;5;28;43mself[39;49m[43m,[49m[43m [49m[38;5;241;43m*[39;49m[43margs[49m[43m,[49m[43m [49m[38;5;241;43m*[39;49m[38;5;241;43m*[39;49m[43mkwargs[49m[43m)[49m

File [0;32m/opt/hostedtoolcache/Python/3.10.9/x64/lib/python3.10/site-packages/plotly/io/_kaleido.py:268[0m, in [0;36mwrite_image[0;34m(fig, file, format, scale, width, height, validate, engine)[0m
[1;32m    252[0m             [38;5;28;01mraise[39;00m [38;5;167;01mValueError[39;00m(
[1;32m    253[0m                 [38;5;124;03m"""[39;00m
[1;32m    254[0m [38;5;124;03mCannot infer image type from output path '{file}'.[39;00m
[0;32m   (...)[0m
[1;32m    262[0m                 )
[1;32m    263[0m             )
[1;32m    265[0m     [38;5;66;03m# Request image[39;00m
[1;32m    266[0m     [38;5;66;03m# -------------[39;00m
[1;32m    267[0m     [38;5;66;03m# Do this first so we don't create a file if image conversion fails[39;00m
[0;32m--> 268[0m     img_data [38;5;241m=[39m [43mto_image[49m[43m([49m
[1;32m    269[0m [43m        [49m[43mfig[49m[43m,[49m
[1;32m    270[0m [43m        [49m[38;5;28;43mformat[39;49m[38;5;241;43m=[39;49m[38;5;28;43mformat[39;49m[43m,[49m
[1;32m    271[0m [43m        [49m[43mscale[49m[38;5;241;43m=[39;49m[43mscale[49m[43m,[49m
[1;32m    272[0m [43m        [49m[43mwidth[49m[38;5;241;43m=[39;49m[43mwidth[49m[43m,[49m
[1;32m    273[0m [43m        [49m[43mheight[49m[38;5;241;43m=[39;49m[43mheight[49m[43m,[49m
[1;32m    274[0m [43m        [49m[43mvalidate[49m[38;5;241;43m=[39;49m[43mvalidate[49m[43m,[49m
[1;32m    275[0m [43m        [49m[43mengine[49m[38;5;241;43m=[39;49m[43mengine[49m[43m,[49m
[1;32m    276[0m [43m    [49m[43m)[49m
[1;32m    278[0m     [38;5;66;03m# Open file[39;00m
[1;32m    279[0m     [38;5;66;03m# ---------[39;00m
[1;32m    280[0m     [38;5;28;01mif[39;00m path [38;5;129;01mis[39;00m [38;5;28;01mNone[39;00m:
[1;32m    281[0m         [38;5;66;03m# We previously failed to make sense of `file` as a pathlib object.[39;00m
[1;32m    282[0m         [38;5;66;03m# Attempt to write to `file` as an open file descriptor.[39;00m

File [0;32m/opt/hostedtoolcache/Python/3.10.9/x64/lib/python3.10/site-packages/plotly/io/_kaleido.py:134[0m, in [0;36mto_image[0;34m(fig, format, width, height, scale, validate, engine)[0m
[1;32m    132[0m     [38;5;66;03m# Raise informative error message if Kaleido is not installed[39;00m
[1;32m    133[0m     [38;5;28;01mif[39;00m scope [38;5;129;01mis[39;00m [38;5;28;01mNone[39;00m:
[0;32m--> 134[0m         [38;5;28;01mraise[39;00m [38;5;167;01mValueError[39;00m(
[1;32m    135[0m             [38;5;124;03m"""[39;00m
[1;32m    136[0m [38;5;124;03mImage export using the "kaleido" engine requires the kaleido package,[39;00m
[1;32m    137[0m [38;5;124;03mwhich can be installed using pip:[39;00m
[1;32m    138[0m [38;5;124;03m    $ pip install -U kaleido[39;00m
[1;32m    139[0m [38;5;124;03m"""[39;00m
[1;32m    140[0m         )
[1;32m    142[0m     [38;5;66;03m# Validate figure[39;00m
[1;32m    143[0m     [38;5;66;03m# ---------------[39;00m
[1;32m    144[0m     fig_dict [38;5;241m=[39m validate_coerce_fig_to_dict(fig, validate)

[0;31mValueError[0m: 
Image export using the "kaleido" engine requires the kaleido package,
which can be installed using pip:
    $ pip install -U kaleido

ValueError: 
Image export using the "kaleido" engine requires the kaleido package,
which can be installed using pip:
    $ pip install -U kaleido


